Workbook

Sheet Summary
A1: Annex A Coverage Summary
A2: All figures calculate from the Annex A Mapping sheet. Change an "Applicable?" cell there and this page updates.
A4: Metric | B4: Value
A5: Annex A controls (ISO/IEC 27001:2022) | B5: =COUNTA('Annex A Mapping'!$A$5:$A$97) -> 93
A6: Marked applicable | B6: =COUNTIF('Annex A Mapping'!$D$5:$D$97,"Yes") -> 93
A7: Marked not applicable | B7: =COUNTIF('Annex A Mapping'!$D$5:$D$97,"No") -> 0
A8: Controls linked to at least one register risk | B8: =COUNTIF('Annex A Mapping'!$G$5:$G$97,">0") -> 55
A9: Controls with no linked risk (baseline, confirm) | B9: =COUNTIFS('Annex A Mapping'!$D$5:$D$97,"Yes",'Annex A Mapping'!$G$5:$G$97,0) -> 38
A10: Coverage of applicable controls by register | B10: =IF(B6=0,0,COUNTIFS('Annex A Mapping'!$D$5:$D$97,"Yes",'Annex A Mapping'!$G$5:$G$97,">0")/B6) -> 0.59139785
A11: Risk-to-control links | B11: =COUNTA('Risk-Control Links'!$A$2:$A$130) -> 129
A12: Controls partially implemented (a linked risk has Weak controls) | B12: =COUNTIF('Annex A Mapping'!$J$5:$J$97,"Partially implemented") -> 28
A13: High-priority controls (linked risk residual >= 12) | B13: =COUNTIF('Annex A Mapping'!$K$5:$K$97,"High") -> 15
A15: By Annex A theme
A16: Theme | B16: Controls | C16: Applicable | D16: Linked to a risk | E16: Partially implemented | F16: High priority
A17: 5 Organizational | B17: =COUNTIF('Annex A Mapping'!$B$5:$B$97,A17) -> 37 | C17: =COUNTIFS('Annex A Mapping'!$B$5:$B$97,A17,'Annex A Mapping'!$D$5:$D$97,"Yes") -> 37 | D17: =COUNTIFS('Annex A Mapping'!$B$5:$B$97,A17,'Annex A Mapping'!$G$5:$G$97,">0") -> 23 | E17: =COUNTIFS('Annex A Mapping'!$B$5:$B$97,A17,'Annex A Mapping'!$J$5:$J$97,"Partially implemented") -> 11 | F17: =COUNTIFS('Annex A Mapping'!$B$5:$B$97,A17,'Annex A Mapping'!$K$5:$K$97,"High") -> 4
A18: 6 People | B18: =COUNTIF('Annex A Mapping'!$B$5:$B$97,A18) -> 8 | C18: =COUNTIFS('Annex A Mapping'!$B$5:$B$97,A18,'Annex A Mapping'!$D$5:$D$97,"Yes") -> 8 | D18: =COUNTIFS('Annex A Mapping'!$B$5:$B$97,A18,'Annex A Mapping'!$G$5:$G$97,">0") -> 5 | E18: =COUNTIFS('Annex A Mapping'!$B$5:$B$97,A18,'Annex A Mapping'!$J$5:$J$97,"Partially implemented") -> 1 | F18: =COUNTIFS('Annex A Mapping'!$B$5:$B$97,A18,'Annex A Mapping'!$K$5:$K$97,"High") -> 0
A19: 7 Physical | B19: =COUNTIF('Annex A Mapping'!$B$5:$B$97,A19) -> 14 | C19: =COUNTIFS('Annex A Mapping'!$B$5:$B$97,A19,'Annex A Mapping'!$D$5:$D$97,"Yes") -> 14 | D19: =COUNTIFS('Annex A Mapping'!$B$5:$B$97,A19,'Annex A Mapping'!$G$5:$G$97,">0") -> 1 | E19: =COUNTIFS('Annex A Mapping'!$B$5:$B$97,A19,'Annex A Mapping'!$J$5:$J$97,"Partially implemented") -> 0 | F19: =COUNTIFS('Annex A Mapping'!$B$5:$B$97,A19,'Annex A Mapping'!$K$5:$K$97,"High") -> 0
A20: 8 Technological | B20: =COUNTIF('Annex A Mapping'!$B$5:$B$97,A20) -> 34 | C20: =COUNTIFS('Annex A Mapping'!$B$5:$B$97,A20,'Annex A Mapping'!$D$5:$D$97,"Yes") -> 34 | D20: =COUNTIFS('Annex A Mapping'!$B$5:$B$97,A20,'Annex A Mapping'!$G$5:$G$97,">0") -> 26 | E20: =COUNTIFS('Annex A Mapping'!$B$5:$B$97,A20,'Annex A Mapping'!$J$5:$J$97,"Partially implemented") -> 16 | F20: =COUNTIFS('Annex A Mapping'!$B$5:$B$97,A20,'Annex A Mapping'!$K$5:$K$97,"High") -> 11
A21: Total | B21: =SUM(B17:B20) -> 93 | C21: =SUM(C17:C20) -> 93 | D21: =SUM(D17:D20) -> 55 | E21: =SUM(E17:E20) -> 28 | F21: =SUM(F17:F20) -> 15
A23: Notes and assumptions
A24: 1. Linked risks are parsed from "ISO 27001 A.x.y" references in the register's Framework Mapping column. Risks without such references (for example climate, supply chain and workforce risks) are not mapped here.
A25: 2. "Implementation status" and "Priority" are formula-driven indicators, not audit findings. "Partially implemented" means at least one linked risk has Weak control effectiveness in the register.
A26: 3. All 93 controls default to "Applicable = Yes". Exclusions must be justified in the Statement of Applicability and approved by management; none are proposed here.
A27: 4. Controls with no linked risk are baseline controls. Confirm evidence and applicability during the next risk assessment cycle.
A28: 5. Register references use the 2022 numbering of Annex A (93 controls in 4 themes).

Sheet Annex A Mapping
A1: ISO/IEC 27001:2022 Annex A: Control Mapping and Statement of Applicability (draft)
A2: Meridian Provisions Group (fictional). Blue = input you can edit. Black = formula. Linked risks come from the Framework Mapping column of the Enterprise Risk Register v1.0. Status and priority are INDICATIVE and must be validated with evidence.
A4: Control ID | B4: Theme | C4: Control | D4: Applicable? (Yes/No) | E4: Justification for inclusion / exclusion | F4: Linked risk IDs | G4: # linked risks | H4: Highest residual score linked | I4: # links with Weak control | J4: Implementation status (indicative) | K4: Priority (indicative) | L4: Suggested owner (from linked risks) | M4: Next step (treatment plan of highest-scoring linked risk) | N4: Evidence / document ref (to complete)
A5: A.5.1 | B5: 5 Organizational | C5: Policies for information security | D5: Yes | E5: Baseline ISO 27001 control; no register risk mapped yet. Confirm applicability and evidence. | G5: =COUNTIF('Risk-Control Links'!$D$2:$D$130,A5) -> 0 | H5: =_xlfn.MAXIFS('Risk-Control Links'!$E$2:$E$130,'Risk-Control Links'!$D$2:$D$130,A5) -> 0 | I5: =COUNTIFS('Risk-Control Links'!$D$2:$D$130,A5,'Risk-Control Links'!$F$2:$F$130,"Weak") -> 0 | J5: =IF(D5<>"Yes","Not applicable",IF(G5=0,"Not assessed",IF(I5>0,"Partially implemented","Largely in place - validate"))) -> Not assessed | K5: =IF(D5<>"Yes","-",IF(G5=0,"Baseline - confirm",IF(H5>=12,"High",IF(I5>0,"Medium","Low")))) -> Baseline - confirm
A6: A.5.2 | B6: 5 Organizational | C6: Information security roles and responsibilities | D6: Yes | E6: Baseline ISO 27001 control; no register risk mapped yet. Confirm applicability and evidence. | G6: =COUNTIF('Risk-Control Links'!$D$2:$D$130,A6) -> 0 | H6: =_xlfn.MAXIFS('Risk-Control Links'!$E$2:$E$130,'Risk-Control Links'!$D$2:$D$130,A6) -> 0 | I6: =COUNTIFS('Risk-Control Links'!$D$2:$D$130,A6,'Risk-Control Links'!$F$2:$F$130,"Weak") -> 0 | J6: =IF(D6<>"Yes","Not applicable",IF(G6=0,"Not assessed",IF(I6>0,"Partially implemented","Largely in place - validate"))) -> Not assessed | K6: =IF(D6<>"Yes","-",IF(G6=0,"Baseline - confirm",IF(H6>=12,"High",IF(I6>0,"Medium","Low")))) -> Baseline - confirm
A7: A.5.3 | B7: 5 Organizational | C7: Segregation of duties | D7: Yes | E7: Treats register risk(s): R-011, R-026. | F7: R-011, R-026 | G7: =COUNTIF('Risk-Control Links'!$D$2:$D$130,A7) -> 2 | H7: =_xlfn.MAXIFS('Risk-Control Links'!$E$2:$E$130,'Risk-Control Links'!$D$2:$D$130,A7) -> 6 | I7: =COUNTIFS('Risk-Control Links'!$D$2:$D$130,A7,'Risk-Control Links'!$F$2:$F$130,"Weak") -> 0 | J7: =IF(D7<>"Yes","Not applicable",IF(G7=0,"Not assessed",IF(I7>0,"Partially implemented","Largely in place - validate"))) -> Largely in place - validate | K7: =IF(D7<>"Yes","-",IF(G7=0,"Baseline - confirm",IF(H7>=12,"High",IF(I7>0,"Medium","Low")))) -> Low | L7: Chief Financial Officer | M7: R-011: Introduce out-of-band codeword verification for executive payment requests; run deepfake awareness drills.
A8: A.5.4 | B8: 5 Organizational | C8: Management responsibilities | D8: Yes | E8: Baseline ISO 27001 control; no register risk mapped yet. Confirm applicability and evidence. | G8: =COUNTIF('Risk-Control Links'!$D$2:$D$130,A8) -> 0 | H8: =_xlfn.MAXIFS('Risk-Control Links'!$E$2:$E$130,'Risk-Control Links'!$D$2:$D$130,A8) -> 0 | I8: =COUNTIFS('Risk-Control Links'!$D$2:$D$130,A8,'Risk-Control Links'!$F$2:$F$130,"Weak") -> 0 | J8: =IF(D8<>"Yes","Not applicable",IF(G8=0,"Not assessed",IF(I8>0,"Partially implemented","Largely in place - validate"))) -> Not assessed | K8: =IF(D8<>"Yes","-",IF(G8=0,"Baseline - confirm",IF(H8>=12,"High",IF(I8>0,"Medium","Low")))) -> Baseline - confirm
A9: A.5.5 | B9: 5 Organizational | C9: Contact with authorities | D9: Yes | E9: Baseline ISO 27001 control; no register risk mapped yet. Confirm applicability and evidence. | G9: =COUNTIF('Risk-Control Links'!$D$2:$D$130,A9) -> 0 | H9: =_xlfn.MAXIFS('Risk-Control Links'!$E$2:$E$130,'Risk-Control Links'!$D$2:$D$130,A9) -> 0 | I9: =COUNTIFS('Risk-Control Links'!$D$2:$D$130,A9,'Risk-Control Links'!$F$2:$F$130,"Weak") -> 0 | J9: =IF(D9<>"Yes","Not applicable",IF(G9=0,"Not assessed",IF(I9>0,"Partially implemented","Largely in place - validate"))) -> Not assessed | K9: =IF(D9<>"Yes","-",IF(G9=0,"Baseline - confirm",IF(H9>=12,"High",IF(I9>0,"Medium","Low")))) -> Baseline - confirm
A10: A.5.6 | B10: 5 Organizational | C10: Contact with special interest groups | D10: Yes | E10: Baseline ISO 27001 control; no register risk mapped yet. Confirm applicability and evidence. | G10: =COUNTIF('Risk-Control Links'!$D$2:$D$130,A10) -> 0 | H10: =_xlfn.MAXIFS('Risk-Control Links'!$E$2:$E$130,'Risk-Control Links'!$D$2:$D$130,A10) -> 0 | I10: =COUNTIFS('Risk-Control Links'!$D$2:$D$130,A10,'Risk-Control Links'!$F$2:$F$130,"Weak") -> 0 | J10: =IF(D10<>"Yes","Not applicable",IF(G10=0,"Not assessed",IF(I10>0,"Partially implemented","Largely in place - validate"))) -> Not assessed | K10: =IF(D10<>"Yes","-",IF(G10=0,"Baseline - confirm",IF(H10>=12,"High",IF(I10>0,"Medium","Low")))) -> Baseline - confirm
A11: A.5.7 | B11: 5 Organizational | C11: Threat intelligence | D11: Yes | E11: Treats register risk(s): R-062, R-063. | F11: R-062, R-063 | G11: =COUNTIF('Risk-Control Links'!$D$2:$D$130,A11) -> 2 | H11: =_xlfn.MAXIFS('Risk-Control Links'!$E$2:$E$130,'Risk-Control Links'!$D$2:$D$130,A11) -> 8 | I11: =COUNTIFS('Risk-Control Links'!$D$2:$D$130,A11,'Risk-Control Links'!$F$2:$F$130,"Weak") -> 0 | J11: =IF(D11<>"Yes","Not applicable",IF(G11=0,"Not assessed",IF(I11>0,"Partially implemented","Largely in place - validate"))) -> Largely in place - validate | K11: =IF(D11<>"Yes","-",IF(G11=0,"Baseline - confirm",IF(H11>=12,"High",IF(I11>0,"Medium","Low")))) -> Low | L11: Chief Information Security Officer | M11: R-062: Run quarterly threat hunting; join industry information-sharing group.
A12: A.5.8 | B12: 5 Organizational | C12: Information security in project management | D12: Yes | E12: Baseline ISO 27001 control; no register risk mapped yet. Confirm applicability and evidence. | G12: =COUNTIF('Risk-Control Links'!$D$2:$D$130,A12) -> 0 | H12: =_xlfn.MAXIFS('Risk-Control Links'!$E$2:$E$130,'Risk-Control Links'!$D$2:$D$130,A12) -> 0 | I12: =COUNTIFS('Risk-Control Links'!$D$2:$D$130,A12,'Risk-Control Links'!$F$2:$F$130,"Weak") -> 0 | J12: =IF(D12<>"Yes","Not applicable",IF(G12=0,"Not assessed",IF(I12>0,"Partially implemented","Largely in place - validate"))) -> Not assessed | K12: =IF(D12<>"Yes","-",IF(G12=0,"Baseline - confirm",IF(H12>=12,"High",IF(I12>0,"Medium","Low")))) -> Baseline - confirm
A13: A.5.9 | B13: 5 Organizational | C13: Inventory of information and other associated assets | D13: Yes | E13: Treats register risk(s): R-033, R-053. | F13: R-033, R-053 | G13: =COUNTIF('Risk-Control Links'!$D$2:$D$130,A13) -> 2 | H13: =_xlfn.MAXIFS('Risk-Control Links'!$E$2:$E$130,'Risk-Control Links'!$D$2:$D$130,A13) -> 12 | I13: =COUNTIFS('Risk-Control Links'!$D$2:$D$130,A13,'Risk-Control Links'!$F$2:$F$130,"Weak") -> 1 | J13: =IF(D13<>"Yes","Not applicable",IF(G13=0,"Not assessed",IF(I13>0,"Partially implemented","Largely in place - validate"))) -> Partially implemented | K13: =IF(D13<>"Yes","-",IF(G13=0,"Baseline - confirm",IF(H13>=12,"High",IF(I13>0,"Medium","Low")))) -> High | L13: Chief Information Officer | M13: R-033: Decommission or migrate EOL systems; apply compensating controls until retired.
A14: A.5.10 | B14: 5 Organizational | C14: Acceptable use of information and other associated assets | D14: Yes | E14: Treats register risk(s): R-053. | F14: R-053 | G14: =COUNTIF('Risk-Control Links'!$D$2:$D$130,A14) -> 1 | H14: =_xlfn.MAXIFS('Risk-Control Links'!$E$2:$E$130,'Risk-Control Links'!$D$2:$D$130,A14) -> 6 | I14: =COUNTIFS('Risk-Control Links'!$D$2:$D$130,A14,'Risk-Control Links'!$F$2:$F$130,"Weak") -> 0 | J14: =IF(D14<>"Yes","Not applicable",IF(G14=0,"Not assessed",IF(I14>0,"Partially implemented","Largely in place - validate"))) -> Largely in place - validate | K14: =IF(D14<>"Yes","-",IF(G14=0,"Baseline - confirm",IF(H14>=12,"High",IF(I14>0,"Medium","Low")))) -> Low | L14: Chief Information Officer | M14: R-053: Accept residual risk; review SaaS discovery quarterly and onboard high-use tools.
A15: A.5.11 | B15: 5 Organizational | C15: Return of assets | D15: Yes | E15: Baseline ISO 27001 control; no register risk mapped yet. Confirm applicability and evidence. | G15: =COUNTIF('Risk-Control Links'!$D$2:$D$130,A15) -> 0 | H15: =_xlfn.MAXIFS('Risk-Control Links'!$E$2:$E$130,'Risk-Control Links'!$D$2:$D$130,A15) -> 0 | I15: =COUNTIFS('Risk-Control Links'!$D$2:$D$130,A15,'Risk-Control Links'!$F$2:$F$130,"Weak") -> 0 | J15: =IF(D15<>"Yes","Not applicable",IF(G15=0,"Not assessed",IF(I15>0,"Partially implemented","Largely in place - validate"))) -> Not assessed | K15: =IF(D15<>"Yes","-",IF(G15=0,"Baseline - confirm",IF(H15>=12,"High",IF(I15>0,"Medium","Low")))) -> Baseline - confirm
A16: A.5.12 | B16: 5 Organizational | C16: Classification of information | D16: Yes | E16: Treats register risk(s): R-042. | F16: R-042 | G16: =COUNTIF('Risk-Control Links'!$D$2:$D$130,A16) -> 1 | H16: =_xlfn.MAXIFS('Risk-Control Links'!$E$2:$E$130,'Risk-Control Links'!$D$2:$D$130,A16) -> 9 | I16: =COUNTIFS('Risk-Control Links'!$D$2:$D$130,A16,'Risk-Control Links'!$F$2:$F$130,"Weak") -> 1 | J16: =IF(D16<>"Yes","Not applicable",IF(G16=0,"Not assessed",IF(I16>0,"Partially implemented","Largely in place - validate"))) -> Partially implemented | K16: =IF(D16<>"Yes","-",IF(G16=0,"Baseline - confirm",IF(H16>=12,"High",IF(I16>0,"Medium","Low")))) -> Medium | L16: Head of Data Governance | M16: R-042: Roll out auto-labelling; enforce retention and deletion on file shares.
A17: A.5.13 | B17: 5 Organizational | C17: Labelling of information | D17: Yes | E17: Treats register risk(s): R-042. | F17: R-042 | G17: =COUNTIF('Risk-Control Links'!$D$2:$D$130,A17) -> 1 | H17: =_xlfn.MAXIFS('Risk-Control Links'!$E$2:$E$130,'Risk-Control Links'!$D$2:$D$130,A17) -> 9 | I17: =COUNTIFS('Risk-Control Links'!$D$2:$D$130,A17,'Risk-Control Links'!$F$2:$F$130,"Weak") -> 1 | J17: =IF(D17<>"Yes","Not applicable",IF(G17=0,"Not assessed",IF(I17>0,"Partially implemented","Largely in place - validate"))) -> Partially implemented | K17: =IF(D17<>"Yes","-",IF(G17=0,"Baseline - confirm",IF(H17>=12,"High",IF(I17>0,"Medium","Low")))) -> Medium | L17: Head of Data Governance | M17: R-042: Roll out auto-labelling; enforce retention and deletion on file shares.
A18: A.5.14 | B18: 5 Organizational | C18: Information transfer | D18: Yes | E18: Treats register risk(s): R-046, R-059. | F18: R-046, R-059 | G18: =COUNTIF('Risk-Control Links'!$D$2:$D$130,A18) -> 2 | H18: =_xlfn.MAXIFS('Risk-Control Links'!$E$2:$E$130,'Risk-Control Links'!$D$2:$D$130,A18) -> 9 | I18: =COUNTIFS('Risk-Control Links'!$D$2:$D$130,A18,'Risk-Control Links'!$F$2:$F$130,"Weak") -> 0 | J18: =IF(D18<>"Yes","Not applicable",IF(G18=0,"Not assessed",IF(I18>0,"Partially implemented","Largely in place - validate"))) -> Largely in place - validate | K18: =IF(D18<>"Yes","-",IF(G18=0,"Baseline - confirm",IF(H18>=12,"High",IF(I18>0,"Medium","Low")))) -> Low | L18: Head of Data Governance | M18: R-059: Add external-sender banners and lookalike domain monitoring; run finance fraud drills.
A19: A.5.15 | B19: 5 Organizational | C19: Access control | D19: Yes | E19: Treats register risk(s): R-026, R-052. | F19: R-026, R-052 | G19: =COUNTIF('Risk-Control Links'!$D$2:$D$130,A19) -> 2 | H19: =_xlfn.MAXIFS('Risk-Control Links'!$E$2:$E$130,'Risk-Control Links'!$D$2:$D$130,A19) -> 9 | I19: =COUNTIFS('Risk-Control Links'!$D$2:$D$130,A19,'Risk-Control Links'!$F$2:$F$130,"Weak") -> 0 | J19: =IF(D19<>"Yes","Not applicable",IF(G19=0,"Not assessed",IF(I19>0,"Partially implemented","Largely in place - validate"))) -> Largely in place - validate | K19: =IF(D19<>"Yes","-",IF(G19=0,"Baseline - confirm",IF(H19>=12,"High",IF(I19>0,"Medium","Low")))) -> Low | L19: Chief Financial Officer | M19: R-052: Adopt least-privilege roles through CIEM; remove unused permissions.
A20: A.5.16 | B20: 5 Organizational | C20: Identity management | D20: Yes | E20: Treats register risk(s): R-025, R-029. | F20: R-025, R-029 | G20: =COUNTIF('Risk-Control Links'!$D$2:$D$130,A20) -> 2 | H20: =_xlfn.MAXIFS('Risk-Control Links'!$E$2:$E$130,'Risk-Control Links'!$D$2:$D$130,A20) -> 6 | I20: =COUNTIFS('Risk-Control Links'!$D$2:$D$130,A20,'Risk-Control Links'!$F$2:$F$130,"Weak") -> 2 | J20: =IF(D20<>"Yes","Not applicable",IF(G20=0,"Not assessed",IF(I20>0,"Partially implemented","Largely in place - validate"))) -> Partially implemented | K20: =IF(D20<>"Yes","-",IF(G20=0,"Baseline - confirm",IF(H20>=12,"High",IF(I20>0,"Medium","Low")))) -> Medium | L20: Chief Information Officer | M20: R-025: Integrate HR system with identity provider for automated deprovisioning within 24 hours.
A21: A.5.17 | B21: 5 Organizational | C21: Authentication information | D21: Yes | E21: Treats register risk(s): R-027, R-050, R-070. | F21: R-027, R-050, R-070 | G21: =COUNTIF('Risk-Control Links'!$D$2:$D$130,A21) -> 3 | H21: =_xlfn.MAXIFS('Risk-Control Links'!$E$2:$E$130,'Risk-Control Links'!$D$2:$D$130,A21) -> 9 | I21: =COUNTIFS('Risk-Control Links'!$D$2:$D$130,A21,'Risk-Control Links'!$F$2:$F$130,"Weak") -> 3 | J21: =IF(D21<>"Yes","Not applicable",IF(G21=0,"Not assessed",IF(I21>0,"Partially implemented","Largely in place - validate"))) -> Partially implemented | K21: =IF(D21<>"Yes","-",IF(G21=0,"Baseline - confirm",IF(H21>=12,"High",IF(I21>0,"Medium","Low")))) -> Medium | L21: Chief Information Security Officer | M21: R-027: Inventory all service accounts; migrate secrets to vault with automatic rotation.
A22: A.5.18 | B22: 5 Organizational | C22: Access rights | D22: Yes | E22: Treats register risk(s): R-023, R-025, R-026, R-029. | F22: R-023, R-025, R-026, R-029 | G22: =COUNTIF('Risk-Control Links'!$D$2:$D$130,A22) -> 4 | H22: =_xlfn.MAXIFS('Risk-Control Links'!$E$2:$E$130,'Risk-Control Links'!$D$2:$D$130,A22) -> 8 | I22: =COUNTIFS('Risk-Control Links'!$D$2:$D$130,A22,'Risk-Control Links'!$F$2:$F$130,"Weak") -> 2 | J22: =IF(D22<>"Yes","Not applicable",IF(G22=0,"Not assessed",IF(I22>0,"Partially implemented","Largely in place - validate"))) -> Partially implemented | K22: =IF(D22<>"Yes","-",IF(G22=0,"Baseline - confirm",IF(H22>=12,"High",IF(I22>0,"Medium","Low")))) -> Medium | L22: Chief Information Security Officer | M22: R-023: Complete tiered admin model; enforce just-in-time admin access; rotate break-glass credentials.
A23: A.5.19 | B23: 5 Organizational | C23: Information security in supplier relationships | D23: Yes | E23: Treats register risk(s): R-066, R-074. | F23: R-066, R-074 | G23: =COUNTIF('Risk-Control Links'!$D$2:$D$130,A23) -> 2 | H23: =_xlfn.MAXIFS('Risk-Control Links'!$E$2:$E$130,'Risk-Control Links'!$D$2:$D$130,A23) -> 9 | I23: =COUNTIFS('Risk-Control Links'!$D$2:$D$130,A23,'Risk-Control Links'!$F$2:$F$130,"Weak") -> 1 | J23: =IF(D23<>"Yes","Not applicable",IF(G23=0,"Not assessed",IF(I23>0,"Partially implemented","Largely in place - validate"))) -> Partially implemented | K23: =IF(D23<>"Yes","-",IF(G23=0,"Baseline - confirm",IF(H23>=12,"High",IF(I23>0,"Medium","Low")))) -> Medium | L23: Chief Procurement Officer | M23: R-066: Extend due diligence to Tier-2 vendors; confirm cyber insurance covers contingent business interruption.
A24: A.5.20 | B24: 5 Organizational | C24: Addressing information security within supplier agreements | D24: Yes | E24: Treats register risk(s): R-066, R-073. | F24: R-066, R-073 | G24: =COUNTIF('Risk-Control Links'!$D$2:$D$130,A24) -> 2 | H24: =_xlfn.MAXIFS('Risk-Control Links'!$E$2:$E$130,'Risk-Control Links'!$D$2:$D$130,A24) -> 9 | I24: =COUNTIFS('Risk-Control Links'!$D$2:$D$130,A24,'Risk-Control Links'!$F$2:$F$130,"Weak") -> 1 | J24: =IF(D24<>"Yes","Not applicable",IF(G24=0,"Not assessed",IF(I24>0,"Partially implemented","Largely in place - validate"))) -> Partially implemented | K24: =IF(D24<>"Yes","-",IF(G24=0,"Baseline - confirm",IF(H24>=12,"High",IF(I24>0,"Medium","Low")))) -> Medium | L24: Chief Procurement Officer | M24: R-066: Extend due diligence to Tier-2 vendors; confirm cyber insurance covers contingent business interruption.
A25: A.5.21 | B25: 5 Organizational | C25: Managing information security in the ICT supply chain | D25: Yes | E25: Treats register risk(s): R-067, R-072, R-074. | F25: R-067, R-072, R-074 | G25: =COUNTIF('Risk-Control Links'!$D$2:$D$130,A25) -> 3 | H25: =_xlfn.MAXIFS('Risk-Control Links'!$E$2:$E$130,'Risk-Control Links'!$D$2:$D$130,A25) -> 12 | I25: =COUNTIFS('Risk-Control Links'!$D$2:$D$130,A25,'Risk-Control Links'!$F$2:$F$130,"Weak") -> 1 | J25: =IF(D25<>"Yes","Not applicable",IF(G25=0,"Not assessed",IF(I25>0,"Partially implemented","Largely in place - validate"))) -> Partially implemented | K25: =IF(D25<>"Yes","-",IF(G25=0,"Baseline - confirm",IF(H25>=12,"High",IF(I25>0,"Medium","Low")))) -> High | L25: Chief Procurement Officer | M25: R-067: Move MSP access to just-in-time with session recording; add right-to-audit clauses.
A26: A.5.22 | B26: 5 Organizational | C26: Monitoring, review and change management of supplier services | D26: Yes | E26: Treats register risk(s): R-066, R-067, R-072, R-073. | F26: R-066, R-067, R-072, R-073 | G26: =COUNTIF('Risk-Control Links'!$D$2:$D$130,A26) -> 4 | H26: =_xlfn.MAXIFS('Risk-Control Links'!$E$2:$E$130,'Risk-Control Links'!$D$2:$D$130,A26) -> 12 | I26: =COUNTIFS('Risk-Control Links'!$D$2:$D$130,A26,'Risk-Control Links'!$F$2:$F$130,"Weak") -> 1 | J26: =IF(D26<>"Yes","Not applicable",IF(G26=0,"Not assessed",IF(I26>0,"Partially implemented","Largely in place - validate"))) -> Partially implemented | K26: =IF(D26<>"Yes","-",IF(G26=0,"Baseline - confirm",IF(H26>=12,"High",IF(I26>0,"Medium","Low")))) -> High | L26: Chief Procurement Officer | M26: R-067: Move MSP access to just-in-time with session recording; add right-to-audit clauses.
A27: A.5.23 | B27: 5 Organizational | C27: Information security for use of cloud services | D27: Yes | E27: Treats register risk(s): R-047, R-053. | F27: R-047, R-053 | G27: =COUNTIF('Risk-Control Links'!$D$2:$D$130,A27) -> 2 | H27: =_xlfn.MAXIFS('Risk-Control Links'!$E$2:$E$130,'Risk-Control Links'!$D$2:$D$130,A27) -> 8 | I27: =COUNTIFS('Risk-Control Links'!$D$2:$D$130,A27,'Risk-Control Links'!$F$2:$F$130,"Weak") -> 0 | J27: =IF(D27<>"Yes","Not applicable",IF(G27=0,"Not assessed",IF(I27>0,"Partially implemented","Largely in place - validate"))) -> Largely in place - validate | K27: =IF(D27<>"Yes","-",IF(G27=0,"Baseline - confirm",IF(H27>=12,"High",IF(I27>0,"Medium","Low")))) -> Low | L27: Head of Cloud Platform | M27: R-047: Enforce policy-as-code guardrails; auto-remediate public storage.
... A30: A.5.26 | B30: 5 Organizational | C30: Response to information security incidents | D30: Yes | E30: Treats register risk(s): R-058. | F30: R-058 | G30: =COUNTIF('Risk-Control Links'!$D$2:$D$130,A30) -> 1 | H30: =_xlfn.MAXIFS('Risk-Control Links'!$E$2:$E$130,'Risk-Control Links'!$D$2:$D$130,A30) -> 6 | I30: =COUNTIFS('Risk-Control Links'!$D$2:$D$130,A30,'Risk-Control Links'!$F$2:$F$130,"Weak") -> 0 | J30: =IF(D30<>"Yes","Not applicable",IF(G30=0,"Not assessed",IF(I30>0,"Partially implemented","Largely in place - validate"))) -> Largely in place - validate | K30: =IF(D30<>"Yes","-",IF(G30=0,"Baseline - confirm",IF(H30>=12,"High",IF(I30>0,"Medium","Low")))) -> Low | L30: Chief Information Security Officer | M30: R-058: Hold biannual executive tabletop exercises; update communications playbooks.
A31: A.5.27 | B31: 5 Organizational | C31: Learning from information security incidents | D31: Yes | E31: Baseline ISO 27001 control; no register risk mapped yet. Confirm applicability and evidence. | G31: =COUNTIF('Risk-Control Links'!$D$2:$D$130,A31) -> 0 | H31: =_xlfn.MAXIFS('Risk-Control Links'!$E$2:$E$130,'Risk-Control Links'!$D$2:$D$130,A31) -> 0 | I31: =COUNTIFS('Risk-Control Links'!$D$2:$D$130,A31,'Risk-Control Links'!$F$2:$F$130,"Weak") -> 0 | J31: =IF(D31<>"Yes","Not applicable",IF(G31=0,"Not assessed",IF(I31>0,"Partially implemented","Largely in place - validate"))) -> Not assessed | K31: =IF(D31<>"Yes","-",IF(G31=0,"Baseline - confirm",IF(H31>=12,"High",IF(I31>0,"Medium","Low")))) -> Baseline - confirm
A32: A.5.28 | B32: 5 Organizational | C32: Collection of evidence | D32: Yes | E32: Baseline ISO 27001 control; no register risk mapped yet. Confirm applicability and evidence. | G32: =COUNTIF('Risk-Control Links'!$D$2:$D$130,A32) -> 0 | H32: =_xlfn.MAXIFS('Risk-Control Links'!$E$2:$E$130,'Risk-Control Links'!$D$2:$D$130,A32) -> 0 | I32: =COUNTIFS('Risk-Control Links'!$D$2:$D$130,A32,'Risk-Control Links'!$F$2:$F$130,"Weak") -> 0 | J32: =IF(D32<>"Yes","Not applicable",IF(G32=0,"Not assessed",IF(I32>0,"Partially implemented","Largely in place - validate"))) -> Not assessed | K32: =IF(D32<>"Yes","-",IF(G32=0,"Baseline - confirm",IF(H32>=12,"High",IF(I32>0,"Medium","Low")))) -> Baseline - confirm
A33: A.5.29 | B33: 5 Organizational | C33: Information security during disruption | D33: Yes | E33: Treats register risk(s): R-071. | F33: R-071 | G33: =COUNTIF('Risk-Control Links'!$D$2:$D$130,A33) -> 1 | H33: =_xlfn.MAXIFS('Risk-Control Links'!$E$2:$E$130,'Risk-Control Links'!$D$2:$D$130,A33) -> 6 | I33: =COUNTIFS('Risk-Control Links'!$D$2:$D$130,A33,'Risk-Control Links'!$F$2:$F$130,"Weak") -> 0 | J33: =IF(D33<>"Yes","Not applicable",IF(G33=0,"Not assessed",IF(I33>0,"Partially implemented","Largely in place - validate"))) -> Largely in place - validate | K33: =IF(D33<>"Yes","-",IF(G33=0,"Baseline - confirm",IF(H33>=12,"High",IF(I33>0,"Medium","Low")))) -> Low | L33: Chief Information Officer | M33: R-071: Run annual failover test to secondary region; evaluate multi-cloud for critical workloads.
A34: A.5.30 | B34: 5 Organizational | C34: ICT readiness for business continuity | D34: Yes | E34: Treats register risk(s): R-071. | F34: R-071 | G34: =COUNTIF('Risk-Control Links'!$D$2:$D$130,A34) -> 1 | H34: =_xlfn.MAXIFS('Risk-Control Links'!$E$2:$E$130,'Risk-Control Links'!$D$2:$D$130,A34) -> 6 | I34: =COUNTIFS('Risk-Control Links'!$D$2:$D$130,A34,'Risk-Control Links'!$F$2:$F$130,"Weak") -> 0 | J34: =IF(D34<>"Yes","Not applicable",IF(G34=0,"Not assessed",IF(I34>0,"Partially implemented","Largely in place - validate"))) -> Largely in place - validate | K34: =IF(D34<>"Yes","-",IF(G34=0,"Baseline - confirm",IF(H34>=12,"High",IF(I34>0,"Medium","Low")))) -> Low | L34: Chief Information Officer | M34: R-071: Run annual failover test to secondary region; evaluate multi-cloud for critical workloads.
A35: A.5.31 | B35: 5 Organizational | C35: Legal, statutory, regulatory and contractual requirements | D35: Yes | E35: Treats register risk(s): R-043, R-064. | F35: R-043, R-064 | G35: =COUNTIF('Risk-Control Links'!$D$2:$D$130,A35) -> 2 | H35: =_xlfn.MAXIFS('Risk-Control Links'!$E$2:$E$130,'Risk-Control Links'!$D$2:$D$130,A35) -> 6 | I35: =COUNTIFS('Risk-Control Links'!$D$2:$D$130,A35,'Risk-Control Links'!$F$2:$F$130,"Weak") -> 0 | J35: =IF(D35<>"Yes","Not applicable",IF(G35=0,"Not assessed",IF(I35>0,"Partially implemented","Largely in place - validate"))) -> Largely in place - validate | K35: =IF(D35<>"Yes","-",IF(G35=0,"Baseline - confirm",IF(H35>=12,"High",IF(I35>0,"Medium","Low")))) -> Low | L35: General Counsel | M35: R-043: Complete transfer impact assessments for all vendors; map data flows.
A36: A.5.32 | B36: 5 Organizational | C36: Intellectual property rights | D36: Yes | E36: Baseline ISO 27001 control; no register risk mapped yet. Confirm applicability and evidence. | G36: =COUNTIF('Risk-Control Links'!$D$2:$D$130,A36) -> 0 | H36: =_xlfn.MAXIFS('Risk-Control Links'!$E$2:$E$130,'Risk-Control Links'!$D$2:$D$130,A36) -> 0 | I36: =COUNTIFS('Risk-Control Links'!$D$2:$D$130,A36,'Risk-Control Links'!$F$2:$F$130,"Weak") -> 0 | J36: =IF(D36<>"Yes","Not applicable",IF(G36=0,"Not assessed",IF(I36>0,"Partially implemented","Largely in place - validate"))) -> Not assessed | K36: =IF(D36<>"Yes","-",IF(G36=0,"Baseline - confirm",IF(H36>=12,"High",IF(I36>0,"Medium","Low")))) -> Baseline - confirm
A37: A.5.33 | B37: 5 Organizational | C37: Protection of records | D37: Yes | E37: Baseline ISO 27001 control; no register risk mapped yet. Confirm applicability and evidence. | G37: =COUNTIF('Risk-Control Links'!$D$2:$D$130,A37) -> 0 | H37: =_xlfn.MAXIFS('Risk-Control Links'!$E$2:$E$130,'Risk-Control Links'!$D$2:$D$130,A37) -> 0 | I37: =COUNTIFS('Risk-Control Links'!$D$2:$D$130,A37,'Risk-Control Links'!$F$2:$F$130,"Weak") -> 0 | J37: =IF(D37<>"Yes","Not applicable",IF(G37=0,"Not assessed",IF(I37>0,"Partially implemented","Largely in place - validate"))) -> Not assessed | K37: =IF(D37<>"Yes","-",IF(G37=0,"Baseline - confirm",IF(H37>=12,"High",IF(I37>0,"Medium","Low")))) -> Baseline - confirm
A38: A.5.34 | B38: 5 Organizational | C38: Privacy and protection of PII | D38: Yes | E38: Treats register risk(s): R-039, R-043, R-064. | F38: R-039, R-043, R-064 | G38: =COUNTIF('Risk-Control Links'!$D$2:$D$130,A38) -> 3 | H38: =_xlfn.MAXIFS('Risk-Control Links'!$E$2:$E$130,'Risk-Control Links'!$D$2:$D$130,A38) -> 8 | I38: =COUNTIFS('Risk-Control Links'!$D$2:$D$130,A38,'Risk-Control Links'!$F$2:$F$130,"Weak") -> 0 | J38: =IF(D38<>"Yes","Not applicable",IF(G38=0,"Not assessed",IF(I38>0,"Partially implemented","Largely in place - validate"))) -> Largely in place - validate | K38: =IF(D38<>"Yes","-",IF(G38=0,"Baseline - confirm",IF(H38>=12,"High",IF(I38>0,"Medium","Low")))) -> Low | L38: General Counsel | M38: R-039: Refresh ROPA; implement field-level encryption for HR and loyalty data.
A39: A.5.35 | B39: 5 Organizational | C39: Independent review of information security | D39: Yes | E39: Baseline ISO 27001 control; no register risk mapped yet. Confirm applicability and evidence. | G39: =COUNTIF('Risk-Control Links'!$D$2:$D$130,A39) -> 0 | H39: =_xlfn.MAXIFS('Risk-Control Links'!$E$2:$E$130,'Risk-Control Links'!$D$2:$D$130,A39) -> 0 | I39: =COUNTIFS('Risk-Control Links'!$D$2:$D$130,A39,'Risk-Control Links'!$F$2:$F$130,"Weak") -> 0 | J39: =IF(D39<>"Yes","Not applicable",IF(G39=0,"Not assessed",IF(I39>0,"Partially implemented","Largely in place - validate"))) -> Not assessed | K39: =IF(D39<>"Yes","-",IF(G39=0,"Baseline - confirm",IF(H39>=12,"High",IF(I39>0,"Medium","Low")))) -> Baseline - confirm
A40: A.5.36 | B40: 5 Organizational | C40: Compliance with policies, rules and standards for information security | D40: Yes | E40: Baseline ISO 27001 control; no register risk mapped yet. Confirm applicability and evidence. | G40: =COUNTIF('Risk-Control Links'!$D$2:$D$130,A40) -> 0 | H40: =_xlfn.MAXIFS('Risk-Control Links'!$E$2:$E$130,'Risk-Control Links'!$D$2:$D$130,A40) -> 0 | I40: =COUNTIFS('Risk-Control Links'!$D$2:$D$130,A40,'Risk-Control Links'!$F$2:$F$130,"Weak") -> 0 | J40: =IF(D40<>"Yes","Not applicable",IF(G40=0,"Not assessed",IF(I40>0,"Partially implemented","Largely in place - validate"))) -> Not assessed | K40: =IF(D40<>"Yes","-",IF(G40=0,"Baseline - confirm",IF(H40>=12,"High",IF(I40>0,"Medium","Low")))) -> Baseline - confirm
A41: A.5.37 | B41: 5 Organizational | C41: Documented operating procedures | D41: Yes | E41: Baseline ISO 27001 control; no register risk mapped yet. Confirm applicability and evidence. | G41: =COUNTIF('Risk-Control Links'!$D$2:$D$130,A41) -> 0 | H41: =_xlfn.MAXIFS('Risk-Control Links'!$E$2:$E$130,'Risk-Control Links'!$D$2:$D$130,A41) -> 0 | I41: =COUNTIFS('Risk-Control Links'!$D$2:$D$130,A41,'Risk-Control Links'!$F$2:$F$130,"Weak") -> 0 | J41: =IF(D41<>"Yes","Not applicable",IF(G41=0,"Not assessed",IF(I41>0,"Partially implemented","Largely in place - validate"))) -> Not assessed | K41: =IF(D41<>"Yes","-",IF(G41=0,"Baseline - confirm",IF(H41>=12,"High",IF(I41>0,"Medium","Low")))) -> Baseline - confirm
A42: A.6.1 | B42: 6 People | C42: Screening | D42: Yes | E42: Treats register risk(s): R-041, R-060. | F42: R-041, R-060 | G42: =COUNTIF('Risk-Control Links'!$D$2:$D$130,A42) -> 2 | H42: =_xlfn.MAXIFS('Risk-Control Links'!$E$2:$E$130,'Risk-Control Links'!$D$2:$D$130,A42) -> 6 | I42: =COUNTIFS('Risk-Control Links'!$D$2:$D$130,A42,'Risk-Control Links'!$F$2:$F$130,"Weak") -> 0 | J42: =IF(D42<>"Yes","Not applicable",IF(G42=0,"Not assessed",IF(I42>0,"Partially implemented","Largely in place - validate"))) -> Largely in place - validate | K42: =IF(D42<>"Yes","-",IF(G42=0,"Baseline - confirm",IF(H42>=12,"High",IF(I42>0,"Medium","Low")))) -> Low | L42: Chief Information Security Officer | M42: R-041: Deploy user behaviour analytics; extend DLP to cloud storage.
A43: A.6.2 | B43: 6 People | C43: Terms and conditions of employment | D43: Yes | E43: Baseline ISO 27001 control; no register risk mapped yet. Confirm applicability and evidence. | G43: =COUNTIF('Risk-Control Links'!$D$2:$D$130,A43) -> 0 | H43: =_xlfn.MAXIFS('Risk-Control Links'!$E$2:$E$130,'Risk-Control Links'!$D$2:$D$130,A43) -> 0 | I43: =COUNTIFS('Risk-Control Links'!$D$2:$D$130,A43,'Risk-Control Links'!$F$2:$F$130,"Weak") -> 0 | J43: =IF(D43<>"Yes","Not applicable",IF(G43=0,"Not assessed",IF(I43>0,"Partially implemented","Largely in place - validate"))) -> Not assessed | K43: =IF(D43<>"Yes","-",IF(G43=0,"Baseline - confirm",IF(H43>=12,"High",IF(I43>0,"Medium","Low")))) -> Baseline - confirm
...

Sheet Risk-Control Links
A1: Risk ID | B1: Risk title | C1: Category | D1: Annex A control | E1: Residual score | F1: Control effectiveness | G1: Within appetite? | H1: Treatment plan (from register) | I1: Risk owner
A2: R-008 | B2: Confidential data leakage through generative AI tools | C2: Technology & AI | D2: A.8.12 | E2: 9 | F2: Adequate | G2: Yes | H2: Deploy DLP rules for external AI services; publish AI tool register; mandatory AI-use training. | I2: Chief Information Security Officer
A3: R-011 | B3: Deepfake-enabled payment fraud and executive impersonation | C3: Cyber: Identity & Access | D3: A.5.3 | E3: 6 | F3: Adequate | G3: Yes | H3: Introduce out-of-band codeword verification for executive payment requests; run deepfake awareness drills. | I3: Chief Financial Officer
A4: R-011 | B4: Deepfake-enabled payment fraud and executive impersonation | C4: Cyber: Identity & Access | D4: A.6.3 | E4: 6 | F4: Adequate | G4: Yes | H4: Introduce out-of-band codeword verification for executive payment requests; run deepfake awareness drills. | I4: Chief Financial Officer
A5: R-012 | B5: Ransomware targeting plant operational technology (OT) | C5: Cyber: OT & Third-Party | D5: A.8.22 | E5: 12 | F5: Weak | G5: No | H5: Segment remaining 5 plants; build OT asset inventory with passive monitoring; run manual-mode production drills. | I5: Chief Information Security Officer
A6: R-013 | B6: Phishing and credential theft targeting remote workers | C6: Cyber: Identity & Access | D6: A.6.3 | E6: 9 | F6: Adequate | G6: Yes | H6: Roll out phishing-resistant MFA for finance, HR and admins; gate access on device compliance. | I6: Chief Information Security Officer
A7: R-013 | B7: Phishing and credential theft targeting remote workers | C7: Cyber: Identity & Access | D7: A.6.7 | E7: 9 | F7: Adequate | G7: Yes | H7: Roll out phishing-resistant MFA for finance, HR and admins; gate access on device compliance. | I7: Chief Information Security Officer
A8: R-013 | B8: Phishing and credential theft targeting remote workers | C8: Cyber: Identity & Access | D8: A.8.5 | E8: 9 | F8: Adequate | G8: Yes | H8: Roll out phishing-resistant MFA for finance, HR and admins; gate access on device compliance. | I8: Chief Information Security Officer
A9: R-014 | B9: Hybrid work weakens security and compliance controls | C9: Workforce & Operating Model | D9: A.6.7 | E9: 6 | F9: Adequate | G9: Yes | H9: Move to zero-trust network access; restrict BYOD to virtual desktop; refresh remote working policy. | I9: Chief Information Officer
A10: R-014 | B10: Hybrid work weakens security and compliance controls | C10: Workforce & Operating Model | D10: A.7.9 | E10: 6 | F10: Adequate | G10: Yes | H10: Move to zero-trust network access; restrict BYOD to virtual desktop; refresh remote working policy. | I10: Chief Information Officer
A11: R-014 | B11: Hybrid work weakens security and compliance controls | C11: Workforce & Operating Model | D11: A.8.1 | E11: 6 | F11: Adequate | G11: Yes | H11: Move to zero-trust network access; restrict BYOD to virtual desktop; refresh remote working policy. | I11: Chief Information Officer
A12: R-023 | B12: Compromise of privileged and domain admin accounts | C12: Cyber: Identity & Access | D12: A.5.18 | E12: 8 | F12: Adequate | G12: Yes | H12: Complete tiered admin model; enforce just-in-time admin access; rotate break-glass credentials. | I12: Chief Information Security Officer
A13: R-023 | B13: Compromise of privileged and domain admin accounts | C13: Cyber: Identity & Access | D13: A.8.2 | E13: 8 | F13: Adequate | G13: Yes | H13: Complete tiered admin model; enforce just-in-time admin access; rotate break-glass credentials. | I13: Chief Information Security Officer
... A130: R-074 | B130: Fourth-party cyber exposure through supplier subcontractors | C130: Cyber: OT & Third-Party | D130: A.5.21 | E130: 6 | F130: Weak | G130: Yes | H130: Require subcontractor lists and flow-down security clauses for critical vendors. | I130: Chief Procurement Officer
